Workbook

Sheet Literacy Rate
A1: STATE/UT | B1: 1951 | C1: 1961 | D1: 1971 | E1: 1981 | F1: 1991 | G1: 2001 | H1: 2011
A2: Andaman & Nicobar Islands | B2: 30.3 | C2: 40.07 | D2: 51.15 | E2: 63.19 | F2: 73.02 | G2: 81.3 | H2: 86.63
A3: Andhra Pradesh | B3: - | C3: 21.19 | D3: 24.57 | E3: 35.66 | F3: 44.08 | G3: 60.47 | H3: 67.02
A4: Arunachal Pradesh | B4: - | C4: 7.13 | D4: 11.29 | E4: 25.55 | F4: 41.59 | G4: 54.34 | H4: 65.39
A5: Assam | B5: 18.53 | C5: 32.95 | D5: 33.94 | E5: - | F5: 52.89 | G5: 63.25 | H5: 72.19
A6: Bihar | B6: 13.49 | C6: 21.95 | D6: 23.17 | E6: 32.32 | F6: 37.49 | G6: 47 | H6: 61.8
A7: Chandigarh | B7: - | C7: - | D7: 70.43 | E7: 74.8 | F7: 77.81 | G7: 81.94 | H7: 86.05
A8: Chhattisgarh | B8: 9.41 | C8: 18.14 | D8: 24.08 | E8: 32.63 | F8: 42.91 | G8: 64.66 | H8: 70.28
A9: Dadra & Nagar Haveli | B9: - | C9: - | D9: 18.13 | E9: 32.9 | F9: 40.71 | G9: 57.63 | H9: 76.24
A10: Daman & Diu | B10: - | C10: - | D10: - | E10: - | F10: 71.2 | G10: 78.18 | H10: 87.1
A11: Delhi | B11: - | C11: 61.95 | D11: 65.08 | E11: 71.94 | F11: 75.29 | G11: 81.67 | H11: 86.21
A12: Goa | B12: 23.48 | C12: 35.41 | D12: 51.96 | E12: 65.71 | F12: 75.51 | G12: 82.01 | H12: 88.7
A13: Gujarat | B13: 21.82 | C13: 31.47 | D13: 36.95 | E13: 44.92 | F13: 61.29 | G13: 69.14 | H13: 78.03
A14: Haryana | B14: - | C14: - | D14: 25.71 | E14: 37.13 | F14: 55.85 | G14: 67.91 | H14: 75.55
A15: Himachal Pradesh | B15: - | C15: - | D15: - | E15: - | F15: 63.86 | G15: 76.48 | H15: 82.8
A16: Jammu & Kashmir | B16: - | C16: 12.95 | D16: 21.71 | E16: 30.64 | F16: - | G16: 55.52 | H16: 67.16
A17: Jharkhand | B17: 12.93 | C17: 21.14 | D17: 23.87 | E17: 35.03 | F17: 41.39 | G17: 53.56 | H17: 66.41
A18: Karnataka | B18: - | C18: 29.8 | D18: 36.83 | E18: 46.21 | F18: 56.04 | G18: 66.6 | H18: 75.37
A19: Kerala | B19: 47.18 | C19: 55.08 | D19: 69.75 | E19: 78.85 | F19: 89.81 | G19: 90.86 | H19: 94
A20: Lakshadweep | B20: 15.23 | C20: 27.15 | D20: 51.76 | E20: 68.42 | F20: 81.78 | G20: 86.66 | H20: 91.85
A21: Madhya Pradesh | B21: 13.16 | C21: 21.41 | D21: 27.27 | E21: 38.63 | F21: 44.67 | G21: 63.74 | H21: 69.32
A22: Maharashtra | B22: 27.91 | C22: 35.08 | D22: 45.77 | E22: 57.24 | F22: 64.87 | G22: 76.88 | H22: 82.34
A23: Manipur | B23: 12.57 | C23: 36.04 | D23: 38.47 | E23: 49.66 | F23: 59.89 | G23: 70.5 | H23: 79.2
A24: Meghalaya | B24: - | C24: 26.92 | D24: 29.49 | E24: 42.05 | F24: 49.1 | G24: 62.56 | H24: 74.43
A25: Mizoram | B25: 31.14 | C25: 44.01 | D25: 53.8 | E25: 59.88 | F25: 82.26 | G25: 88.8 | H25: 91.33
A26: Nagaland | B26: 10.52 | C26: 21.95 | D26: 33.78 | E26: 50.28 | F26: 61.65 | G26: 66.59 | H26: 79.6
A27: Odisha | B27: 15.8 | C27: 21.66 | D27: 26.18 | E27: 33.62 | F27: 49.09 | G27: 63.08 | H27: 72.89
A28: Puducherry | B28: - | C28: 43.65 | D28: 53.38 | E28: 65.14 | F28: 74.74 | G28: 81.24 | H28: 85.85
A29: Punjab | B29: - | C29: - | D29: 34.12 | E29: 43.37 | F29: 58.51 | G29: 69.65 | H29: 75.84
A30: Rajasthan | B30: 8.5 | C30: 18.12 | D30: 22.57 | E30: 30.11 | F30: 38.55 | G30: 60.41 | H30: 66.11
A31: Sikkim | B31: - | C31: - | D31: 17.74 | E31: 34.05 | F31: 56.94 | G31: 68.81 | H31: 81.42
A32: Tamil Nadu | B32: - | C32: 36.39 | D32: 45.4 | E32: 54.39 | F32: 62.66 | G32: 73.45 | H32: 80.09
A33: Tripura | B33: - | C33: 20.24 | D33: 30.98 | E33: 50.1 | F33: 60.44 | G33: 73.19 | H33: 87.22
A34: Uttar Pradesh | B34: 12.02 | C34: 20.87 | D34: 23.99 | E34: 32.65 | F34: 40.71 | G34: 56.27 | H34: 67.68
A35: Uttarakhand | B35: 18.93 | C35: 18.05 | D35: 33.26 | E35: 46.06 | F35: 57.75 | G35: 71.62 | H35: 78.82
A36: West Bengal | B36: 24.61 | C36: 34.46 | D36: 38.86 | E36: 48.65 | F36: 57.7 | G36: 68.64 | H36: 76.26
A37: ALL INDIA | B37: 18.33 | C37: 28.3 | D37: 34.45 | E37: 43.57 | F37: 52.21 | G37: 64.84 | H37: 72.99

Sheet Assumed Literacy Rate
A1: STATE/UT | B1: 2001 | C1: 2002 | D1: 2003 | E1: 2004 | F1: 2005 | G1: 2006 | H1: 2007 | I1: 2008 | J1: 2009 | K1: 2010 | L1: 2011 | M1: Rate of change
A2: Andaman & Nicobar Islands | B2: 81.3 | C2: =(L2-B2)/10 + B2 -> 81.833 | D2: =(L2-B2)/10 +C2 -> 82.366 | E2: =(L2-B2)/10 +D2 -> 82.899 | F2: =(L2-B2)/10 +E2 -> 83.432 | G2: =(L2-B2)/10 +F2 -> 83.965 | H2: =(L2-B2)/10 +G2 -> 84.498 | I2: =(L2-B2)/10 +H2 -> 85.031 | J2: =(L2-B2)/10 +I2 -> 85.564 | K2: =(L2-B2)/10 +J2 -> 86.097 | L2: 86.63 | M2: =(L2-B2)/10 -> 0.533
A3: Andhra Pradesh | B3: 60.47 | C3: =(L3-B3)/10 + B3 -> 61.125 | D3: =(L3-B3)/10 +C3 -> 61.78 | E3: =(L3-B3)/10 +D3 -> 62.435 | F3: =(L3-B3)/10 +E3 -> 63.09 | G3: =(L3-B3)/10 +F3 -> 63.745 | H3: =(L3-B3)/10 +G3 -> 64.4 | I3: =(L3-B3)/10 +H3 -> 65.055 | J3: =(L3-B3)/10 +I3 -> 65.71 | K3: =(L3-B3)/10 +J3 -> 66.365 | L3: 67.02 | M3: =(L3-B3)/10 -> 0.655
A4: Arunachal Pradesh | B4: 54.34 | C4: =(L4-B4)/10 + B4 -> 55.445 | D4: =(L4-B4)/10 +C4 -> 56.55 | E4: =(L4-B4)/10 +D4 -> 57.655 | F4: =(L4-B4)/10 +E4 -> 58.76 | G4: =(L4-B4)/10 +F4 -> 59.865 | H4: =(L4-B4)/10 +G4 -> 60.97 | I4: =(L4-B4)/10 +H4 -> 62.075 | J4: =(L4-B4)/10 +I4 -> 63.18 | K4: =(L4-B4)/10 +J4 -> 64.285 | L4: 65.39 | M4: =(L4-B4)/10 -> 1.105
A5: Assam | B5: 63.25 | C5: =(L5-B5)/10 + B5 -> 64.144 | D5: =(L5-B5)/10 +C5 -> 65.038 | E5: =(L5-B5)/10 +D5 -> 65.932 | F5: =(L5-B5)/10 +E5 -> 66.826 | G5: =(L5-B5)/10 +F5 -> 67.72 | H5: =(L5-B5)/10 +G5 -> 68.614 | I5: =(L5-B5)/10 +H5 -> 69.508 | J5: =(L5-B5)/10 +I5 -> 70.402 | K5: =(L5-B5)/10 +J5 -> 71.296 | L5: 72.19 | M5: =(L5-B5)/10 -> 0.894
A6: Bihar | B6: 47 | C6: =(L6-B6)/10 + B6 -> 48.48 | D6: =(L6-B6)/10 +C6 -> 49.96 | E6: =(L6-B6)/10 +D6 -> 51.44 | F6: =(L6-B6)/10 +E6 -> 52.92 | G6: =(L6-B6)/10 +F6 -> 54.4 | H6: =(L6-B6)/10 +G6 -> 55.88 | I6: =(L6-B6)/10 +H6 -> 57.36 | J6: =(L6-B6)/10 +I6 -> 58.84 | K6: =(L6-B6)/10 +J6 -> 60.32 | L6: 61.8 | M6: =(L6-B6)/10 -> 1.48
A7: Chandigarh | B7: 81.94 | C7: =(L7-B7)/10 + B7 -> 82.351 | D7: =(L7-B7)/10 +C7 -> 82.762 | E7: =(L7-B7)/10 +D7 -> 83.173 | F7: =(L7-B7)/10 +E7 -> 83.584 | G7: =(L7-B7)/10 +F7 -> 83.995 | H7: =(L7-B7)/10 +G7 -> 84.406 | I7: =(L7-B7)/10 +H7 -> 84.817 | J7: =(L7-B7)/10 +I7 -> 85.228 | K7: =(L7-B7)/10 +J7 -> 85.639 | L7: 86.05 | M7: =(L7-B7)/10 -> 0.411
A8: Chhattisgarh | B8: 64.66 | C8: =(L8-B8)/10 + B8 -> 65.222 | D8: =(L8-B8)/10 +C8 -> 65.784 | E8: =(L8-B8)/10 +D8 -> 66.346 | F8: =(L8-B8)/10 +E8 -> 66.908 | G8: =(L8-B8)/10 +F8 -> 67.47 | H8: =(L8-B8)/10 +G8 -> 68.032 | I8: =(L8-B8)/10 +H8 -> 68.594 | J8: =(L8-B8)/10 +I8 -> 69.156 | K8: =(L8-B8)/10 +J8 -> 69.718 | L8: 70.28 | M8: =(L8-B8)/10 -> 0.562
A9: Dadra & Nagar Haveli | B9: 57.63 | C9: =(L9-B9)/10 + B9 -> 59.491 | D9: =(L9-B9)/10 +C9 -> 61.352 | E9: =(L9-B9)/10 +D9 -> 63.213 | F9: =(L9-B9)/10 +E9 -> 65.074 | G9: =(L9-B9)/10 +F9 -> 66.935 | H9: =(L9-B9)/10 +G9 -> 68.796 | I9: =(L9-B9)/10 +H9 -> 70.657 | J9: =(L9-B9)/10 +I9 -> 72.518 | K9: =(L9-B9)/10 +J9 -> 74.379 | L9: 76.24 | M9: =(L9-B9)/10 -> 1.861
A10: Daman & Diu | B10: 78.18 | C10: =(L10-B10)/10 + B10 -> 79.072 | D10: =(L10-B10)/10 +C10 -> 79.964 | E10: =(L10-B10)/10 +D10 -> 80.856 | F10: =(L10-B10)/10 +E10 -> 81.748 | G10: =(L10-B10)/10 +F10 -> 82.64 | H10: =(L10-B10)/10 +G10 -> 83.532 | I10: =(L10-B10)/10 +H10 -> 84.424 | J10: =(L10-B10)/10 +I10 -> 85.316 | K10: =(L10-B10)/10 +J10 -> 86.208 | L10: 87.1 | M10: =(L10-B10)/10 -> 0.892
A11: Delhi | B11: 81.67 | C11: =(L11-B11)/10 + B11 -> 82.124 | D11: =(L11-B11)/10 +C11 -> 82.578 | E11: =(L11-B11)/10 +D11 -> 83.032 | F11: =(L11-B11)/10 +E11 -> 83.486 | G11: =(L11-B11)/10 +F11 -> 83.94 | H11: =(L11-B11)/10 +G11 -> 84.394 | I11: =(L11-B11)/10 +H11 -> 84.848 | J11: =(L11-B11)/10 +I11 -> 85.302 | K11: =(L11-B11)/10 +J11 -> 85.756 | L11: 86.21 | M11: =(L11-B11)/10 -> 0.454
A12: Goa | B12: 82.01 | C12: =(L12-B12)/10 + B12 -> 82.679 | D12: =(L12-B12)/10 +C12 -> 83.348 | E12: =(L12-B12)/10 +D12 -> 84.017 | F12: =(L12-B12)/10 +E12 -> 84.686 | G12: =(L12-B12)/10 +F12 -> 85.355 | H12: =(L12-B12)/10 +G12 -> 86.024 | I12: =(L12-B12)/10 +H12 -> 86.693 | J12: =(L12-B12)/10 +I12 -> 87.362 | K12: =(L12-B12)/10 +J12 -> 88.031 | L12: 88.7 | M12: =(L12-B12)/10 -> 0.669
A13: Gujarat | B13: 69.14 | C13: =(L13-B13)/10 + B13 -> 70.029 | D13: =(L13-B13)/10 +C13 -> 70.918 | E13: =(L13-B13)/10 +D13 -> 71.807 | F13: =(L13-B13)/10 +E13 -> 72.696 | G13: =(L13-B13)/10 +F13 -> 73.585 | H13: =(L13-B13)/10 +G13 -> 74.474 | I13: =(L13-B13)/10 +H13 -> 75.363 | J13: =(L13-B13)/10 +I13 -> 76.252 | K13: =(L13-B13)/10 +J13 -> 77.141 | L13: 78.03 | M13: =(L13-B13)/10 -> 0.889
... A37: ALL INDIA | B37: 64.84 | C37: =(L37-B37)/10 + B37 -> 65.655 | D37: =(L37-B37)/10 +C37 -> 66.47 | E37: =(L37-B37)/10 +D37 -> 67.285 | F37: =(L37-B37)/10 +E37 -> 68.1 | G37: =(L37-B37)/10 +F37 -> 68.915 | H37: =(L37-B37)/10 +G37 -> 69.73 | I37: =(L37-B37)/10 +H37 -> 70.545 | J37: =(L37-B37)/10 +I37 -> 71.36 | K37: =(L37-B37)/10 +J37 -> 72.175 | L37: 72.99 | M37: =(L37-B37)/10 -> 0.815

Sheet Compiled Data
A1: STATE/UT | B1: Year | C1: Total Population | D1: Literacy Rate
A2: Andaman & Nicobar Islands | B2: 2001 | C2: =[1]T_1!$H$5 -> 356 | D2: ='Assumed Literacy Rate'!B2 -> 81.3
A3: Andhra Pradesh | B3: 2001 | D3: ='Assumed Literacy Rate'!B3 -> 60.47
A4: Arunachal Pradesh | B4: 2001 | D4: ='Assumed Literacy Rate'!B4 -> 54.34
A5: Assam | B5: 2001 | D5: ='Assumed Literacy Rate'!B5 -> 63.25
A6: Bihar | B6: 2001 | D6: ='Assumed Literacy Rate'!B6 -> 47
A7: Chandigarh | B7: 2001 | D7: ='Assumed Literacy Rate'!B7 -> 81.94
A8: Chhattisgarh | B8: 2001 | D8: ='Assumed Literacy Rate'!B8 -> 64.66
A9: Dadra & Nagar Haveli | B9: 2001 | D9: ='Assumed Literacy Rate'!B9 -> 57.63
A10: Daman & Diu | B10: 2001 | D10: ='Assumed Literacy Rate'!B10 -> 78.18
A11: Delhi | B11: 2001 | D11: ='Assumed Literacy Rate'!B11 -> 81.67
A12: Goa | B12: 2001 | D12: ='Assumed Literacy Rate'!B12 -> 82.01
A13: Gujarat | B13: 2001 | D13: ='Assumed Literacy Rate'!B13 -> 69.14
A14: Haryana | B14: 2001 | D14: ='Assumed Literacy Rate'!B14 -> 67.91
... A36: West Bengal | B36: 2001 | D36: ='Assumed Literacy Rate'!B36 -> 68.64
A37: Andaman & Nicobar Islands | B37: 2002 | C37: 359 | D37: ='Assumed Literacy Rate'!C2 -> 81.833
A38: Andhra Pradesh | B38: 2002 | D38: ='Assumed Literacy Rate'!C3 -> 61.125
A39: Arunachal Pradesh | B39: 2002 | D39: ='Assumed Literacy Rate'!C4 -> 55.445
A40: Assam | B40: 2002 | D40: ='Assumed Literacy Rate'!C5 -> 64.144
A41: Bihar | B41: 2002 | D41: ='Assumed Literacy Rate'!C6 -> 48.48
A42: Chandigarh | B42: 2002 | D42: ='Assumed Literacy Rate'!C7 -> 82.351
A43: Chhattisgarh | B43: 2002 | D43: ='Assumed Literacy Rate'!C8 -> 65.222
A44: Dadra & Nagar Haveli | B44: 2002 | D44: ='Assumed Literacy Rate'!C9 -> 59.491
A45: Daman & Diu | B45: 2002 | D45: ='Assumed Literacy Rate'!C10 -> 79.072
A46: Delhi | B46: 2002 | D46: ='Assumed Literacy Rate'!C11 -> 82.124
A47: Goa | B47: 2002 | D47: ='Assumed Literacy Rate'!C12 -> 82.679
A48: Gujarat | B48: 2002 | D48: ='Assumed Literacy Rate'!C13 -> 70.029
A49: Haryana | B49: 2002 | D49: ='Assumed Literacy Rate'!C14 -> 68.674
... A71: West Bengal | B71: 2002 | D71: ='Assumed Literacy Rate'!C36 -> 69.402
A72: Andaman & Nicobar Islands | B72: 2003 | C72: 361 | D72: ='Assumed Literacy Rate'!D2 -> 82.366
A73: Andhra Pradesh | B73: 2003 | D73: ='Assumed Literacy Rate'!D3 -> 61.78
A74: Arunachal Pradesh | B74: 2003 | D74: ='Assumed Literacy Rate'!D4 -> 56.55
A75: Assam | B75: 2003 | D75: ='Assumed Literacy Rate'!D5 -> 65.038
A76: Bihar | B76: 2003 | D76: ='Assumed Literacy Rate'!D6 -> 49.96
A77: Chandigarh | B77: 2003 | D77: ='Assumed Literacy Rate'!D7 -> 82.762
A78: Chhattisgarh | B78: 2003 | D78: ='Assumed Literacy Rate'!D8 -> 65.784
A79: Dadra & Nagar Haveli | B79: 2003 | D79: ='Assumed Literacy Rate'!D9 -> 61.352
A80: Daman & Diu | B80: 2003 | D80: ='Assumed Literacy Rate'!D10 -> 79.964
A81: Delhi | B81: 2003 | D81: ='Assumed Literacy Rate'!D11 -> 82.578
A82: Goa | B82: 2003 | D82: ='Assumed Literacy Rate'!D12 -> 83.348
...
